Workbook
Name Countries: #REF!

Sheet Exhibit 1
B2: Exhibit 1 - Project Assumptions
B4: Assumption | C4: Value | D4: Unit | E4: Comments
B5: All Projects
B6: Corporate Tax Rate | C6: 0.21
B7: Risk Free Rate | C7: 0.04
B8: Equity Risk Premium | C8: 0.055
B10: Project Bison - Frontera
B11: Development Cost | C11: 2 | D11: $ (billions) | E11: Split ratably over development years
B12: Production Royalty and Government Take | C12: 0.15 | D12: % of Total Revenue
B13: Direct Operating Expense | C13: 15 | D13: USD/BOE
B14: Overhead Expense | C14: 2 | D14: USD/BOE
B15: Fin. Book Depreciation | C15: 10 | D15: Years | E15: =_xlfn.CONCAT("$",C11,"B Total Value - Straight Line") -> $2B Total Value - Straight Line
B16: Midstream Expense | C16: 2 | D16: USD/BOE
B17: Undiscounted Decommissioning Cost | C17: 200 | D17: MMUSD
B18: Time to Production | C18: 1 | D18: Years | E18: Production starts in Year 2
B21: Project Fennec - Tassili
B22: Development Cost | C22: 5 | D22: $ (billions) | E22: Split ratably over development years
B23: Production Royalty and Government Take | C23: 0.3 | D23: % of Total Revenue
B24: Direct Operating Expense | C24: 14 | D24: USD/BOE
B25: Overhead Expense | C25: 3.5 | D25: USD/BOE
B26: Fin. Book Depreciation | C26: 15 | D26: Years | E26: =_xlfn.CONCAT("$",C22,"B Total Value - Straight Line") -> $5B Total Value - Straight Line
B27: Midstream Expense | C27: 7 | D27: USD/BOE
B28: Undiscounted Decommissioning Cost | C28: 350 | D28: MMUSD
B29: Time to Production | C29: 3 | D29: Years | E29: Production starts in Year 4
B32: Project Puma - Amazonia
B33: Development Cost | C33: 15 | D33: $ (billions) | E33: Split ratably over development years
B34: Production Royalty and Government Take | C34: 0.2 | D34: % of Total Revenue
B35: Direct Operating Expense | C35: 8 | D35: USD/BOE
B36: Overhead Expense | C36: 3.5 | D36: USD/BOE
B37: Fin. Book Depreciation | C37: 25 | D37: Years | E37: =_xlfn.CONCAT("$",C33,"B Total Value - Straight Line") -> $15B Total Value - Straight Line
B38: Midstream Expense | C38: 4 | D38: USD/BOE
B39: Undiscounted Decommissioning Cost | C39: 1000 | D39: MMUSD
B40: Time to Production | C40: 5 | D40: Years | E40: Production starts in Year 6
B44: Notes
B45: 1. Assume depreciation starts in the first production year and ends in the last production year

Sheet Exhibit 2
B2: Exhibit 2 - NorthStar Energy Financial Statements
B4: Consolidated Statement of Income
B5: In Millions of USD | C5: 2024 | D5: 2025 | E5: 2026
B6: Oil Revenue | C6: 27418 | D6: 26083 | E6: 21135
B7: Natural Gas Revenue | C7: 2905 | D7: 2643 | E7: 2382
B8: Natural Gas Liquids Revenue | C8: 6913 | D8: 9247 | E8: 8361
B9: Total Revenue | C9: 37236 | D9: 37973 | E9: 31878
B11: Operating Expenses | C11: 22944 | D11: 22395 | E11: 16005
B12: Exploration | C12: 199 | D12: 228 | E12: 315
B13: General and Administrative Expenses | C13: 360 | D13: 312 | E13: 353
B14: Depreciation Depletion And Amortization | C14: 3604 | D14: 3753 | E14: 4135
B15: Other Operating Expenses | C15: 151 | D15: 226 | E15: 163
B16: Impairments | C16: 337 | D16: - | E16: 7
B17: Total Operating Expenses | C17: 27595 | D17: 26914 | E17: 20978
B19: Operating Income | C19: 9641 | D19: 11059 | E19: 10900
B21: Interest Expense | C21: 1570 | D21: 1368 | E21: 1377
B22: Income Before Income Taxes | C22: 8071 | D22: 9691 | E22: 9523
B23: Income Tax Expense | C23: 1259 | D23: 3635 | E23: 1943
B24: Net Income | C24: 6812 | D24: 6056 | E24: 7580
B26: Consolidated Balance Sheet
B27: In Millions of USD | C27: 2024 | D27: 2025 | E27: 2026
B28: Current Assets
B29: Cash and Equivalents | C29: 2450 | D29: 2450 | E29: 2446
B30: Inventory | C30: 745 | D30: 760 | E30: 638
B31: Accounts Receivable | C31: 3351 | D31: 3418 | E31: 2869
B32: Pre-Paid Expenses, & Other | C32: 559 | D32: 570 | E32: 478
B33: Total Current Assets | C33: 7105 | D33: 7198 | E33: 6431
B34: Non-Current Assets
B35: Property Plant & Equipment - Net | C35: 36687 | D35: 40121 | E35: 45001
B36: Other Non-Current Assets | C36: 341 | D36: 347 | E36: 405
B37: Total Assets | C37: 44133 | D37: 47666 | E37: 51837
B38: Current Liabilities
B39: Accrued Expenses | C39: 600 | D39: 2295 | E39: 1784
B40: Accounts Payable - Trade | C40: 3240 | D40: 3304 | E40: 2774
B41: Current Portion of LT Debt | C41: 1474 | D41: 1213 | E41: 1923
B42: Total Current Liabilities | C42: 5314 | D42: 6812 | E42: 6481
B43: Non Current Liabilities
B44: Long Term Debt | C44: 26274 | D44: 26057 | E44: 24841
B45: Deferred Income Taxes (Liabilities) | C45: 221 | D45: 195 | E45: 192
B46: Asset Retirement Obligation | C46: 1057 | D46: 968 | E46: 628
...

Sheet Exhibit 3
B2: Exhibit 3 - NorthStar Energy Comparable Firms
B4: Company | C4: Stock Price (USD/share) | D4: Shares Outstanding | E4: Market Cap (MUSD) | F4: Total Debt (MUSD) | G4: Noncontrolling Interests (MUSD) | H4: Total EV (MUSD) | I4: Revenue (MUSD) | J4: EBITDA (MUSD) | K4: EBIT (MUSD) | L4: Net Income (MUSD) | M4: Interest Expense (MUSD) | N4: Levered Equity Beta
F5: LTM | G5: LTM | I5: LTM | J5: LTM | K5: LTM | L5: LTM
B6: Company A | C6: 160.6 | D6: 506138710 | E6: 81285877 | F6: 58786280 | G6: 242000 | H6: 140315683 | I6: 61853379 | J6: 21648683 | K6: 15463345 | L6: 10240289 | M6: -1211717 | N6: 1.45
B7: Company B | C7: 108.21 | D7: 891610443 | E7: 96481166 | F7: 38286344 | G7: 43014 | H7: 134811465 | I7: 63826690 | J7: 22339342 | K7: 15956673 | L7: 10564931 | M7: -1183751 | N7: 1.14
B8: Company C | C8: 202.57 | D8: 694600425 | E8: 1.4070521e+08 | F8: 68437320 | G8: 1616000 | H8: 210760518 | I8: 94160393 | J8: 32956138 | K8: 23540098 | L8: 15597475 | M8: -2115970 | N8: 1.77
B9: Company D | C9: 146.18 | D9: 784292830 | E9: 1.1464793e+08 | F9: 37564875 | G9: 241 | H9: 152213751 | I9: 63245795 | J9: 22136028 | K9: 15811449 | L9: 10468425 | M9: -1161445 | N9: 1.16
B10: Company E | C10: 176.18 | D10: 247478882 | E10: 43600829 | F10: 45894882 | G10: 987249 | H10: 90483184 | I10: 39330844 | J10: 13765796 | K10: 9832711 | L10: 6517064 | M10: -945997 | N10: 1.25
B11: Company F | C11: 98.83 | D11: 58264267 | E11: 5758257.5 | F11: 12118484 | G11: 9900 | H11: 17886884 | I11: 16488780 | J11: 5771073 | K11: 4122195 | L11: 2731464 | M11: -374684 | N11: 0.79
B12: Company G | C12: 90.1 | D12: 779090965 | E12: 70196096 | F12: 12855538 | G12: 1922933 | H12: 84974959 | I12: 54703853 | J12: 19146349 | K12: 13675963 | L12: 9036849 | M12: -397472 | N12: 0.92
B13: Company H | C13: 43.55 | D13: 1040759148 | E13: 45325061 | F13: 13498324 | G13: 115200 | H13: 58936231 | I13: 36853951 | J13: 12898883 | K13: 9213488 | L13: 6092350 | M13: -417346 | N13: 1.26
B14: Company I | C14: 72.56 | D14: 49692776 | E14: 3605707.8 | F14: 30183120 | G14: 125617 | H14: 33914585 | I14: 5162212 | J14: 1806774 | K14: 1290553 | L14: 950024 | M14: -933213 | N14: 1.42
B15: Company J | C15: 135.68 | D15: 18036665 | E15: 2447214.7 | F15: 10927581 | G15: NA | H15: 13374767 | I15: 3495475 | J15: 1223416 | K15: 873869 | L15: 591520 | M15: -337863 | N15: 0.71
B16: Company K | C16: 125.63 | D16: 979313394 | E16: 1.2303114e+08 | F16: 45461220 | G16: 93000 | H16: 168583541 | I16: 69288451 | J16: 24250958 | K16: 17322113 | L16: 11472719 | M16: -1405587 | N16: 1.42
B18: Note:
B19: MUSD = thousands USD

Sheet Exhibit 4
B2: Exhibit 4 - Unweighted Geographical Risk Premium (GRP)
B4: Region | C4: GRP
B5: Frontera | C5: 0
B6: Amazonia | C6: 0.03
B7: Tassili | C7: 0.06

Sheet Exhibit 5
B2: Exhibit 5 - Project Bison Production Projections
B4: Production | C4: Units | D4: 2027 | E4: 2028 | F4: 2029 | G4: 2030 | H4: 2031 | I4: 2032 | J4: 2033 | K4: 2034 | L4: 2035 | M4: 2036 | N4: 2037
B5: Oil Equivalent | C5: MBOED | D5: 0 | E5: 75 | F5: 75 | G5: 75 | H5: 74.86 | I5: 74.93 | J5: 74.82 | K5: 74.64 | L5: 74.61 | M5: 74.74 | N5: 74.4
B6: Crude | C6: MBD
B7: Nat Gas | C7: MMSCFD
B8: NGL | C8: MBD

Sheet Exhibit 6
B2: Exhibit 6 - Project Fennec Production Projections
B4: Production | C4: Units | D4: 2027 | E4: 2028 | F4: 2029 | G4: 2030 | H4: 2031 | I4: 2032 | J4: 2033 | K4: 2034 | L4: 2035 | M4: 2036 | N4: 2037 | O4: 2038 | P4: 2039 | Q4: 2040 | R4: 2041 | S4: 2042 | T4: 2043 | U4: 2044
B5: Oil Equivalent | C5: MBOED | D5: 0 | E5: 0 | F5: 0 | G5: 150 | H5: 150 | I5: 150 | J5: 150 | K5: 150 | L5: 150 | M5: 150 | N5: 99.48 | O5: 99.66 | P5: 99.2 | Q5: 80.5 | R5: 50.55 | S5: 25.08 | T5: 25.78 | U5: 27.61 | W5: =SUM(D5:U5) -> 1557.86
B6: Crude | C6: MBD
B7: Nat Gas | C7: MMSCFD
B8: NGL | C8: MBD

Sheet Exhibit 7
B2: Exhibit 7 - Project Puma Production Projections
B4: Production | C4: Units | D4: 2027 | E4: =D4+1 -> 2028 | F4: =E4+1 -> 2029 | G4: =F4+1 -> 2030 | H4: =G4+1 -> 2031 | I4: =H4+1 -> 2032 | J4: =I4+1 -> 2033 | K4: =J4+1 -> 2034 | L4: =K4+1 -> 2035 | ... AG4: =AF4+1 -> 2056
B5: Oil Equivalent | C5: MBOED | D5: 0 | E5: 0 | F5: 0 | G5: 0 | H5: 0 | I5: 300 | J5: 300 | K5: 300 | L5: 300 | M5: 300 | N5: 300 | O5: 300 | P5: 300 | Q5: 300 | R5: 297 | S5: 294.03 | T5: 291.0897 | U5: 288.1788 | V5: 285.29701 | W5: 282.44404 | X5: 279.6196 | Y5: 276.82341 | Z5: 274.05517 | AA5: 271.31462 | AB5: 268.60148 | AC5: 265.91546 | AD5: 263.25631 | AE5: 260.62374 | AF5: 258.01751 | AG5: 255.43733
B6: Crude | C6: MBD
B7: Nat Gas | C7: MMSCFD
B8: NGL | C8: MBD

Sheet Exhibit 8
B2: Exhibit 8 - Disaggregated Production by Project
B4: Source | C4: Composition | D4: Product Type | E4: 2027 | F4: 2028 | G4: 2029 | H4: 2030 | I4: 2031 | J4: 2032 | K4: 2033 | L4: 2034 | M4: 2035 | N4: 2036 | O4: 2037 | P4: 2038 | Q4: 2039 | R4: 2040 | S4: 2041 | T4: 2042 | U4: 2043 | V4: 2044 | W4: 2045 | X4: 2046 | Y4: =X4+1 -> 2047 | Z4: =Y4+1 -> 2048 | AA4: =Z4+1 -> 2049 | AB4: =AA4+1 -> 2050 | AC4: =AB4+1 -> 2051 | AD4: =AC4+1 -> 2052 | AE4: =AD4+1 -> 2053 | AF4: =AE4+1 -> 2054 | ... AM4: =AL4+1 -> 2061
B5: Bison | C5: % | D5: Crude | F5: 0.59 | G5: 0.585 | H5: 0.58 | I5: 0.575 | J5: 0.57 | K5: 0.565 | L5: 0.56 | M5: 0.55 | N5: 0.54 | O5: 0.53
B6: Bison | C6: % | D6: Natural Gas | F6: 0.328 | G6: 0.332 | H6: 0.336 | I6: 0.34 | J6: 0.344 | K6: 0.348 | L6: 0.352 | M6: 0.36 | N6: 0.368 | O6: 0.376
B7: Bison | C7: % | D7: NGL | F7: 0.082 | G7: 0.083 | H7: 0.084 | I7: 0.085 | J7: 0.086 | K7: 0.087 | L7: 0.088 | M7: 0.09 | N7: 0.092 | O7: 0.094
B8: Fennec | C8: % | D8: Crude | H8: 0.35 | I8: 0.34 | J8: 0.33 | K8: 0.32 | L8: 0.31 | M8: 0.3 | N8: 0.29 | O8: 0.28 | P8: 0.27 | Q8: 0.26 | R8: 0.25 | S8: 0.24 | T8: 0.23 | U8: 0.22 | V8: 0.21
B9: Fennec | C9: % | D9: Natural Gas | H9: 0.6125 | I9: 0.6175 | J9: 0.6225 | K9: 0.6275 | L9: 0.6325 | M9: 0.6375 | N9: 0.6425 | O9: 0.6475 | P9: 0.6525 | Q9: 0.6575 | R9: 0.6625 | S9: 0.6675 | T9: 0.6725 | U9: 0.6775 | V9: 0.6825
B10: Fennec | C10: % | D10: NGL | H10: 0.0375 | I10: 0.0425 | J10: 0.0475 | K10: 0.0525 | L10: 0.0575 | M10: 0.0625 | N10: 0.0675 | O10: 0.0725 | P10: 0.0775 | Q10: 0.0825 | R10: 0.0875 | S10: 0.0925 | T10: 0.0975 | U10: 0.1025 | V10: 0.1075
B11: Puma | C11: % | D11: Crude | J11: 0.85 | K11: 0.85 | L11: 0.85 | M11: 0.85 | N11: 0.85 | O11: 0.85 | P11: 0.8475 | Q11: 0.845 | R11: 0.8425 | S11: 0.84 | T11: 0.8375 | U11: 0.835 | V11: 0.8325 | W11: 0.83 | X11: 0.8275 | Y11: 0.825 | Z11: 0.8225 | AA11: 0.82 | AB11: 0.8175 | AC11: 0.815 | AD11: 0.8125 | AE11: 0.81 | AF11: 0.8075 | AG11: 0.805 | AH11: 0.8025
B12: Puma | C12: % | D12: Natural Gas | J12: 0.1 | K12: 0.1 | L12: 0.1 | M12: 0.1 | N12: 0.1 | O12: 0.1 | P12: 0.101 | Q12: 0.102 | R12: 0.103 | S12: 0.104 | T12: 0.105 | U12: 0.106 | V12: 0.107 | W12: 0.108 | X12: 0.109 | Y12: 0.11 | Z12: 0.111 | AA12: 0.112 | AB12: 0.113 | AC12: 0.114 | AD12: 0.115 | AE12: 0.116 | AF12: 0.117 | AG12: 0.118 | AH12: 0.119
B13: Puma | C13: % | D13: NGL | J13: 0.05 | K13: 0.05 | L13: 0.05 | M13: 0.05 | N13: 0.05 | O13: 0.05 | P13: 0.0515 | Q13: 0.053 | R13: 0.0545 | S13: 0.056 | T13: 0.0575 | U13: 0.059 | V13: 0.0605 | W13: 0.062 | X13: 0.0635 | Y13: 0.065 | Z13: 0.0665 | AA13: 0.068 | AB13: 0.0695 | AC13: 0.071 | AD13: 0.0725 | AE13: 0.074 | AF13: 0.0755 | AG13: 0.077 | AH13: 0.0785
B15: Notes
B16: 1. Percentages are shown as % of Total BOE
B17: 2. Oil-equivalent conversion ratio: 6,000 cubic feet of natural gas = 1 barrel of crude oil
B18: 3. Natural gas heating value: 1 MMSCF = 1028 MMBTU
B19: 4. Assume 1 BOE of NGLs = 1 BBL of NGLs
I22: 1028
I23: 3.38
I24: =I22*I23 -> 3474.64

Sheet Exhibit 9
B2: Exhibit 9 - Price Curves by Market
B4: Market Benchmark | C4: Type of Product | D4: Source | E4: Units | F4: 2027 | G4: =F4+1 -> 2028 | H4: =G4+1 -> 2029 | I4: =H4+1 -> 2030 | J4: =I4+1 -> 2031 | K4: =J4+1 -> 2032 | L4: =K4+1 -> 2033 | M4: =L4+1 -> 2034 | N4: =M4+1 -> 2035 | ... AN4: =AM4+1 -> 2061
B5: WTI | C5: Crude | D5: Frontera | E5: USD/BBL | F5: 80.98 | G5: 72.38 | H5: 69.47 | I5: 69.47 | J5: 69.47 | K5: 69.47 | L5: 69.47 | M5: 69.47 | N5: 69.47 | O5: 69.47 | P5: 69.47 | Q5: 69.47 | R5: 69.47 | S5: 69.47 | T5: 69.47 | U5: 69.47 | V5: 69.47 | W5: 69.47 | X5: 69.47 | Y5: 69.47 | Z5: 69.47 | AA5: 69.47 | AB5: 69.47 | AC5: 69.47 | AD5: 69.47 | AE5: 69.47 | AF5: 69.47 | AG5: 69.47 | AH5: 69.47 | AI5: 69.47 | AJ5: 69.47 | AK5: 69.47 | AL5: 69.47 | AM5: 69.47 | AN5: 69.47
B6: Henry Hub | C6: Natural gas | D6: Frontera/Amazonia | E6: USD/MMBTU | F6: 3.06 | G6: 3.38 | H6: 3.38 | I6: 3.38 | J6: 3.38 | K6: 3.38 | L6: 3.38 | M6: 3.38 | N6: 3.38 | O6: 3.38 | P6: 3.38 | Q6: 3.38 | R6: 3.38 | S6: 3.38 | T6: 3.38 | U6: 3.38 | V6: 3.38 | W6: 3.38 | X6: 3.38 | Y6: 3.38 | Z6: 3.38 | AA6: 3.38 | AB6: 3.38 | AC6: 3.38 | AD6: 3.38 | AE6: 3.38 | AF6: 3.38 | AG6: 3.38 | AH6: 3.38 | AI6: 3.38 | AJ6: 3.38 | AK6: 3.38 | AL6: 3.38 | AM6: 3.38 | AN6: 3.38
B7: OPIS | C7: Natural gas liquids | D7: Frontera/Amazonia | E7: USD/BBL | F7: 28.34 | G7: 25.33 | H7: 24.31 | I7: 24.31 | J7: 24.31 | K7: 24.31 | L7: 24.31 | M7: 24.31 | N7: 24.31 | O7: 24.31 | P7: 24.31 | Q7: 24.31 | R7: 24.31 | S7: 24.31 | T7: 24.31 | U7: 24.31 | V7: 24.31 | W7: 24.31 | X7: 24.31 | Y7: 24.31 | Z7: 24.31 | AA7: 24.31 | AB7: 24.31 | AC7: 24.31 | AD7: 24.31 | AE7: 24.31 | AF7: 24.31 | AG7: 24.31 | AH7: 24.31 | AI7: 24.31 | AJ7: 24.31 | AK7: 24.31 | AL7: 24.31 | AM7: 24.31 | AN7: 24.31
B8: Brent | C8: Crude | D8: Tassili/Amazonia | E8: USD/BBL | F8: 86.92 | G8: 77.63 | H8: 74.37 | I8: 74.37 | J8: 74.37 | K8: 74.37 | L8: 74.37 | M8: 74.37 | N8: 74.37 | O8: 74.37 | P8: 74.37 | Q8: 74.37 | R8: 74.37 | S8: 74.37 | T8: 74.37 | U8: 74.37 | V8: 74.37 | W8: 74.37 | X8: 74.37 | Y8: 74.37 | Z8: 74.37 | AA8: 74.37 | AB8: 74.37 | AC8: 74.37 | AD8: 74.37 | AE8: 74.37 | AF8: 74.37 | AG8: 74.37 | AH8: 74.37 | AI8: 74.37 | AJ8: 74.37 | AK8: 74.37 | AL8: 74.37 | AM8: 74.37 | AN8: 74.37
B9: TTF | C9: Natural gas | D9: Tassili | E9: USD/MMBTU | F9: 20.25 | G9: 14.53 | H9: 14.53 | I9: 14.53 | J9: 14.53 | K9: 14.53 | L9: 14.53 | M9: 14.53 | N9: 14.53 | O9: 14.53 | P9: 14.53 | Q9: 14.53 | R9: 14.53 | S9: 14.53 | T9: 14.53 | U9: 14.53 | V9: 14.53 | W9: 14.53 | X9: 14.53 | Y9: 14.53 | Z9: 14.53 | AA9: 14.53 | AB9: 14.53 | AC9: 14.53 | AD9: 14.53 | AE9: 14.53 | AF9: 14.53 | AG9: 14.53 | AH9: 14.53 | AI9: 14.53 | AJ9: 14.53 | AK9: 14.53 | AL9: 14.53 | AM9: 14.53 | AN9: 14.53
B10: Europe (OPIS+3) | C10: Natural gas liquids | D10: Tassili | E10: USD/BBL | F10: 31.34 | G10: 28.33 | H10: 27.31 | I10: 27.31 | J10: 27.31 | K10: 27.31 | L10: 27.31 | M10: 27.31 | N10: 27.31 | O10: 27.31 | P10: 27.31 | Q10: 27.31 | R10: 27.31 | S10: 27.31 | T10: 27.31 | U10: 27.31 | V10: 27.31 | W10: 27.31 | X10: 27.31 | Y10: 27.31 | Z10: 27.31 | AA10: 27.31 | AB10: 27.31 | AC10: 27.31 | AD10: 27.31 | AE10: 27.31 | AF10: 27.31 | AG10: 27.31 | AH10: 27.31 | AI10: 27.31 | AJ10: 27.31 | AK10: 27.31 | AL10: 27.31 | AM10: 27.31 | AN10: 27.31

Sheet Exhibit 10
B2: Exhibit 10 - Carbon Targets
C4: Unit | D4: Bison | E4: Fennec | F4: Puma
B5: Carbon Intensity | C5: kgCO2e/boe | D5: 16 | E5: 19 | F5: 8

Sheet Exhibit 11
B2: Exhibit 11 - Common Abbreviations
B4: Abbreviation | C4: Definition
B5: BBL | C5: Barrels
B6: BOE | C6: Barrels of oil equivalent
B7: BOED | C7: Barrels of oil equivalent per day
B8: BTU | C8: British thermal units
B9: kgCO2e | C9: Kilograms of carbon dioxide equivalent
B10: MBOED | C10: Thousands of barrels of oil equivalent per day
B11: MMBTU | C11: Millions of British thermal units
B12: MMSCFD | C12: Millions of standard cubic feet per day
B13: MMUSD | C13: Millions of US dollars
B14: MTCO2e | C14: Metric tons of carbon dioxide equivalent
B15: MUSD | C15: Thousands of US dollars
... B17: USD | C17: US dollars

Sheet Exhibit 12
C2: Exhibit 12- Debt Capacity Assumptions
C4: Assumptions
C5: Baseline Adj. EBITDA Growth Rate | D5: 0.03
C6: Baseline Free Cash Flow Growth Rate | D6: 0.03
C7: Dividend Growth Rate | D7: 0.05
C8: Base Free Cash Flow before Dividend and Share Repurchases (2027, MMUSD) | D8: 1600
C9: Leverage Ceiling (Net Debt / Adj. EBITDA) | D9: 1.75x
C11: Notes
C12: To simplify the leverage capacity forecast, assume that NorthStar does not repurchase shares after 2026.

Sheet Leverage Analysis - Template
B2: Leverage Analysis
B4: Baseline Adj. EBITDA Growth Rate
B5: Baseline Free Cash Flow Growth Rate
B6: Dividend Growth Rate
B7: Base Free Cash Flow before Dividend and Share Repurchases (2027, MMUSD)
B8: Dividend (2026)
B9: Beginning Adj. EBITDA (2026)
B10: Ending Net Debt (2026)
B11: Leverage Ceiling
B14: Project Puma - Amazonia
B15: Year | C15: 2027 | D15: 2028 | E15: 2029 | F15: 2030 | G15: 2031 | H15: 2032 | I15: 2033 | J15: 2034 | K15: 2035 | L15: 2036 | M15: 2037 | N15: 2038 | O15: 2039 | P15: 2040 | Q15: 2041 | R15: 2042 | S15: 2043 | T15: 2044 | U15: 2045 | V15: 2046 | W15: 2047 | X15: 2048 | Y15: 2049 | Z15: 2050 | AA15: 2051 | AB15: 2052 | AC15: 2053 | AD15: 2054 | AE15: 2055 | AF15: 2056
B16: Baseline Adj. EBITDA
B17: +Project EBITDA
B18: Total Adj. EBITDA
B20: Beginning Net Debt
B21: - Base Free Cash Flow (before dividend)
B22: + Dividends Paid
B23: - Project Unlevered FCF
B24: Ending Net Debt
B26: Net Debt / Adj. EBITDA
B27: Ceiling
B30: Project Fennec - Tassili
B31: Year | C31: 2027 | D31: 2028 | E31: 2029 | F31: 2030 | G31: 2031 | H31: 2032 | I31: 2033 | J31: 2034 | K31: 2035 | L31: 2036 | M31: 2037 | N31: 2038 | O31: 2039 | P31: 2040 | Q31: 2041 | R31: 2042 | S31: 2043 | T31: 2044
B32: Baseline Adj. EBITDA
B33: +Project EBITDA
B34: Total Adj. EBITDA
B36: Beginning Net Debt
B37: - Base Free Cash Flow (before dividend)
B38: + Dividends Paid
B39: - Project Unlevered FCF
B40: Ending Net Debt
B42: Net Debt / Adj. EBITDA
B43: Ceiling
B46: Project Bison - Frontera
B47: Year | C47: 2027 | D47: 2028 | E47: 2029 | F47: 2030 | G47: 2031 | H47: 2032 | I47: 2033 | J47: 2034 | K47: 2035 | L47: 2036 | M47: 2037
B48: Baseline Adj. EBITDA
B49: +Project EBITDA
B50: Total Adj. EBITDA
B52: Beginning Net Debt
B53: - Base Free Cash Flow (before dividend)
...

Sheet Guide
B1: Guide: how the numbers were made, and why Puma does not pass
B2: Read top to bottom. Every number here is a live link to the Puma DCF tab, which links to the case exhibits. Dollars in millions unless noted. Red = a failed test.
B4: Step 1. The production point is fair: Puma really does produce a lot
B5: Peak production (MBOED): Puma | Bison | Fennec | C5: =MAX('Puma DCF'!D17:AG17) -> 300 | D5: =MAX('Bison DCF'!D17:N17) -> 75 | E5: =MAX('Fennec DCF'!D17:U17) -> 150 | F5: Puma is 4x Bison and 2x Fennec at peak. Source: Exhibits 5, 6, 7.
B6: Puma average over its 25 producing years (MBOED) | C6: =AVERAGEIF('Puma DCF'!D17:AG17,">0") -> 284.46817 | F6: Flat at 300 from 2032 to 2040, then a slow decline to about 255 by 2056.
B7: Puma production in 2027 to 2031 (MBOED, total) | C7: =SUM('Puma DCF'!D17:H17) -> 0 | F7: Zero for the first five years.
B8: Puma capex spent in those same five years | C8: =-SUM('Puma DCF'!D38:H38) -> 15000 | F8: Development cost spread evenly over five years (Exhibit 1). Nothing comes back until 2032.
B9: So the claim is right: production is near 300 for most of Puma's life. The case just does not ask which project produces the most. It asks the two questions in Step 2, and it asks them every year starting in 2027.
B11: Step 2. What the case actually tests, in this order
B12: Test | C12: Puma result | F12: Rule and where in the case
B13: 1. Leverage ceiling (hard) | C13: =Summary!E19 -> FAIL | F13: Net debt / Adj. EBITDA at or below 1.75x in EVERY year. Case p.2 and p.6, Exhibit 12.
B14: 2. Dividend growth (hard) | C14: =Summary!E20 -> FAIL | F14: Total dividend +5% every year, no new equity. Any gap is funded with debt, so the debt must stay under the ceiling. Case p.2 and p.7.
B15: 3. Only then: weigh the rest | C15: =IF(Summary!E21="DISQUALIFIED","Not reached","Weigh") -> Not reached | F15: Returns, risk, capital discipline, carbon, production growth. Production growth is the lowest investor priority at 5% (case p.6).
B16: Result | C16: =Summary!E21 -> DISQUALIFIED | F16: Case p.6-7: a project that cannot clear both constraints "cannot be recommended, no matter how high its standalone value".
B18: Step 3. How Puma's cash flow is built (live from the Puma DCF tab)
B19: Line | C19: 2027 (build year) | D19: 2032 (first production) | F19: How it is calculated
B20: Production (MBOED) | C20: ='Puma DCF'!D17 -> 0 | D20: ='Puma DCF'!I17 -> 300 | F20: ="From Exhibit 7" -> From Exhibit 7
B21: Annual volume (million boe) | C21: ='Puma DCF'!D18 -> 0 | D21: ='Puma DCF'!I18 -> 109.5 | F21: ="MBOED x 1,000 x 365 / 1,000,000" -> MBOED x 1,000 x 365 / 1,000,000
B22: Crude revenue | C22: ='Puma DCF'!D26 -> 0 | D22: ='Puma DCF'!I26 -> 6921.9878 | F22: ="Volume x "&TEXT('Puma DCF'!I19,"0%")&" crude share (Exhibit 8) x Brent "&TEXT('Puma DCF'!I22,"0.00")&" USD/bbl (Exhibit 9)" -> Volume x 85% crude share (Exhibit 8) x Brent 74.37 USD/bbl (Exhibit 9)
B23: Gas revenue | C23: ='Puma DCF'!D27 -> 0 | D23: ='Puma DCF'!I27 -> 228.28385 | F23: ="Volume x "&TEXT('Puma DCF'!I20,"0%")&" gas share x Henry Hub "&TEXT('Puma DCF'!I23,"0.00")&" USD/MMBtu x 6 x 1.028 = "&TEXT('Puma DCF'!I25,"0.00")&" USD/boe" -> Volume x 10% gas share x Henry Hub 3.38 USD/MMBtu x 6 x 1.028 = 20.85 USD/boe
B24: NGL revenue | C24: ='Puma DCF'!D28 -> 0 | D24: ='Puma DCF'!I28 -> 133.09725 | F24: ="Volume x "&TEXT('Puma DCF'!I21,"0%")&" NGL share x OPIS "&TEXT('Puma DCF'!I24,"0.00")&" USD/bbl" -> Volume x 5% NGL share x OPIS 24.31 USD/bbl
B25: Total revenue | C25: ='Puma DCF'!D29 -> 0 | D25: ='Puma DCF'!I29 -> 7283.3688 | F25: ="Sum of the three products" -> Sum of the three products
B26: Royalty and government take | C26: ='Puma DCF'!D30 -> 0 | D26: ='Puma DCF'!I30 -> -1456.6738 | F26: =TEXT('Puma DCF'!D5,"0%")&" of total revenue (Exhibit 1)" -> 20% of total revenue (Exhibit 1)
B27: Opex + overhead + midstream | C27: =SUM('Puma DCF'!D31:D33) -> 0 | D27: =SUM('Puma DCF'!I31:I33) -> -1697.25 | F27: =TEXT('Puma DCF'!D6+'Puma DCF'!D7+'Puma DCF'!D8,"0.00")&" USD/boe x volume (8 + 3.5 + 4, Exhibit 1)" -> 15.50 USD/boe x volume (8 + 3.5 + 4, Exhibit 1)
B28: EBITDA | C28: ='Puma DCF'!D34 -> 0 | D28: ='Puma DCF'!I34 -> 4129.4451 | F28: ="Revenue less royalty and operating costs" -> Revenue less royalty and operating costs
B29: Depreciation | C29: ='Puma DCF'!D35 -> 0 | D29: ='Puma DCF'!I35 -> -600 | F29: ="Development cost "&TEXT('Puma DCF'!D4,"#,##0")&" / "&'Puma DCF'!D9&" years, charged from the first production year" -> Development cost 15,000 / 25 years, charged from the first production year
B30: Income tax | C30: ='Puma DCF'!D37 -> 0 | D30: ='Puma DCF'!I37 -> -741.18347 | F30: =TEXT('Puma DCF'!D13,"0%")&" x (EBITDA - depreciation)" -> 21% x (EBITDA - depreciation)
B31: Development capex | C31: ='Puma DCF'!D38 -> -3000 | D31: ='Puma DCF'!I38 -> 0 | F31: ="Development cost "&TEXT('Puma DCF'!D4,"#,##0")&" / "&'Puma DCF'!D11&" development years, charged 2027 to 2031" -> Development cost 15,000 / 5 development years, charged 2027 to 2031
B32: Unlevered free cash flow | C32: ='Puma DCF'!D40 -> -3000 | D32: ='Puma DCF'!I40 -> 3388.2616 | F32: ="EBITDA - tax - capex - decommissioning. This feeds the leverage test." -> EBITDA - tax - capex - decommissioning. This feeds the leverage test.
B33: Carbon cost (valuation only) | C33: ='Puma DCF'!D41 -> 0 | D33: ='Puma DCF'!I41 -> -65.7 | F33: ="Volume x "&'Puma DCF'!D12&" kg/boe x "&'WACC & Inputs'!C5&" USD/t / 1,000 (valuation only; non-cash, not deductible)" -> Volume x 8 kg/boe x 75 USD/t / 1,000 (valuation only; non-cash, not deductible)
B34: Free cash flow for valuation | C34: ='Puma DCF'!D42 -> -3000 | D34: ='Puma DCF'!I42 -> 3322.5616 | F34: ="Free cash flow after carbon. Used for NPV and IRR, not for leverage." -> Free cash flow after carbon. Used for NPV and IRR, not for leverage.
B35: In the 2027 column nothing is produced, so the only cash flow is the 3,000 of capex. That pattern repeats every year to 2031.
B37: Step 4. Is Puma worth doing on its own? Yes, and that is why it looks attractive
C38: Bison | D38: Fennec | E38: Puma
B39: NPV with carbon | C39: =Summary!C10 -> 1074.1462 | D39: =Summary!D10 -> 1419.3545 | E39: =Summary!E10 -> 5615.3517 | F39: Puma has the largest NPV, because of its scale and 25 years of production.
B40: IRR with carbon | C40: =Summary!C11 -> 0.21324519 | D40: =Summary!D11 -> 0.19021177 | E40: =Summary!E11 -> 0.15492591 | F40: It also has the lowest IRR: the value comes from size, not from returns on capital.
B41: WACC used | C41: =Summary!C9 -> 0.086390682 | D41: =Summary!D9 -> 0.12596171 | E41: =Summary!E9 -> 0.10617619
B42: A positive NPV is necessary but not sufficient. The case says the two hard tests come first.
B44: Step 5. Can NorthStar afford it? Puma's borrowing need against NorthStar's borrowing room
B45: Build years only (2027 to 2031), when Puma earns nothing: the test reduces to "can NorthStar add this much debt and stay under 1.75x?"
...

Sheet Summary
B1: Why Puma doesn't work: what the case actually tests
B2: Everything below pulls from the project tabs, which pull from the case exhibits. Change the switches on the WACC & Inputs tab and this page updates. New to this? Start with the Guide tab.
B4: 1. Side by side | C4: Bison | D4: Fennec | E4: Puma | F4: What it tells you
B5: Development capex ($B) | C5: ='Bison DCF'!D4/1000 -> 2 | D5: ='Fennec DCF'!D4/1000 -> 5 | E5: ='Puma DCF'!D4/1000 -> 15
B6: First production year | C6: =2027+'Bison DCF'!D11 -> 2028 | D6: =2027+'Fennec DCF'!D11 -> 2030 | E6: =2027+'Puma DCF'!D11 -> 2032 | F6: Puma: five years of spending before any revenue
B7: Peak production (MBOED) <-- the number the team is focused on | C7: =MAX('Bison DCF'!D17:N17) -> 75 | D7: =MAX('Fennec DCF'!D17:U17) -> 150 | E7: =MAX('Puma DCF'!D17:AG17) -> 300 | F7: Size is not a test in the case (see section 2)
B8: Lifetime volume (MM boe) | C8: =SUM('Bison DCF'!D18:N18) -> 273.02 | D8: =SUM('Fennec DCF'!D18:U18) -> 568.6189 | E8: =SUM('Puma DCF'!D18:AG18) -> 2595.772
B9: WACC used | C9: ='Bison DCF'!D14 -> 0.086390682 | D9: ='Fennec DCF'!D14 -> 0.12596171 | E9: ='Puma DCF'!D14 -> 0.10617619 | F9: Set by the country-risk switch on WACC & Inputs
B10: NPV with carbon ($MM) | C10: ='Bison DCF'!D47 -> 1074.1462 | D10: ='Fennec DCF'!D47 -> 1419.3545 | E10: ='Puma DCF'!D47 -> 5615.3517 | F10: Puma is worth the most on paper...
B11: IRR with carbon | C11: ='Bison DCF'!D48 -> 0.21324519 | D11: ='Fennec DCF'!D48 -> 0.19021177 | E11: ='Puma DCF'!D48 -> 0.15492591 | F11: ...but earns the lowest return on its capital
B12: IRR minus WACC | C12: ='Bison DCF'!D50 -> 0.1268545 | D12: ='Fennec DCF'!D50 -> 0.064250064 | E12: ='Puma DCF'!D50 -> 0.048749715
B13: NPV before carbon ($MM) | C13: ='Bison DCF'!D51 -> 1270.9021 | D13: ='Fennec DCF'!D51 -> 1719.5166 | E13: ='Puma DCF'!D51 -> 5951.52 | F13: Carbon at $75/t trims NPV but changes no ranking
B14: Peak net debt / Adj. EBITDA (ceiling 1.75x) | C14: =MAX('Bison DCF'!D62:N62) -> 1.6363113 | D14: =MAX('Fennec DCF'!D62:U62) -> 1.6697357 | E14: =MAX('Puma DCF'!D62:AG62) -> 2.0901479
B15: Year of peak | C15: =INDEX('Bison DCF'!D16:N16,MATCH(MAX('Bison DCF'!D62:N62),'Bison DCF'!D62:N62,0)) -> 2027 | D15: =INDEX('Fennec DCF'!D16:U16,MATCH(MAX('Fennec DCF'!D62:U62),'Fennec DCF'!D62:U62,0)) -> 2029 | E15: =INDEX('Puma DCF'!D16:AG16,MATCH(MAX('Puma DCF'!D62:AG62),'Puma DCF'!D62:AG62,0)) -> 2031
B16: Years above the ceiling | C16: =COUNTIF('Bison DCF'!D65:N65,"BREACH") -> 0 | D16: =COUNTIF('Fennec DCF'!D65:U65,"BREACH") -> 0 | E16: =COUNTIF('Puma DCF'!D65:AG65,"BREACH") -> 4
B17: First year above the ceiling | C17: =IFERROR(INDEX('Bison DCF'!D16:N16,MATCH("BREACH",'Bison DCF'!D65:N65,0)),"none") -> none | D17: =IFERROR(INDEX('Fennec DCF'!D16:U16,MATCH("BREACH",'Fennec DCF'!D65:U65,0)),"none") -> none | E17: =IFERROR(INDEX('Puma DCF'!D16:AG16,MATCH("BREACH",'Puma DCF'!D65:AG65,0)),"none") -> 2028
B18: Tightest headroom ($MM; negative = over the ceiling) | C18: =MIN('Bison DCF'!D64:N64) -> 1797.475 | D18: =MIN('Fennec DCF'!D64:U64) -> 1346.3018 | E18: =MIN('Puma DCF'!D64:AG64) -> -6052.8832 | F18: Net debt the ceiling still allows in the worst year
B19: HARD TEST 1: leverage at or below 1.75x in every year | C19: =IF(C16=0,"PASS","FAIL") -> PASS | D19: =IF(D16=0,"PASS","FAIL") -> PASS | E19: =IF(E16=0,"PASS","FAIL") -> FAIL
B20: HARD TEST 2: dividend +5%/yr, no new equity (gap funded by debt) | C20: =IF(C19="PASS","PASS","FAIL") -> PASS | D20: =IF(D19="PASS","PASS","FAIL") -> PASS | E20: =IF(E19="PASS","PASS","FAIL") -> FAIL | F20: Debt funding is only allowed up to the ceiling
B21: RESULT | C21: =IF(AND(C19="PASS",C20="PASS"),"ADMISSIBLE","DISQUALIFIED") -> ADMISSIBLE | D21: =IF(AND(D19="PASS",D20="PASS"),"ADMISSIBLE","DISQUALIFIED") -> ADMISSIBLE | E21: =IF(AND(E19="PASS",E20="PASS"),"ADMISSIBLE","DISQUALIFIED") -> DISQUALIFIED | F21: Case p.3: constraints first, then weigh the rest
B23: 2. What the case says you must hit
B24: Benchmark | C24: Type | D24: Where in the case
B25: Net debt / Adj. EBITDA at or below 1.75x in EVERY year | C25: HARD | D25: Case p.2 and p.6; ceiling in Exhibit 12. "A firm cap ... not a soft target."
B26: Total cash dividend spend grows 5% every year, no new equity | C26: HARD | D26: Case p.2 and p.7. Any shortfall is funded with debt.
B27: Only after both pass: weigh returns, risk, capital discipline, carbon | C27: WEIGH | D27: Case p.3: "must first satisfy both firm constraints ... before weighing the remaining tradeoffs"
B28: Carbon intensity from ~18 toward 15 kg CO2e/boe by 2035 | C28: STRATEGIC | D28: Case p.2: an ambition to be weighed, not a pass/fail test
B29: Total production or reserve size | C29: NOT A BENCHMARK | D29: No minimum production or reserve target appears anywhere in the case
B31: Investor priorities (case p.6 survey chart) | C31: Weight
B32: Dividend growth | C32: 0.45 | D32: Read from the pie chart on case p.6 (typed in; check against the PDF)
B33: Risk-adjusted returns | C33: 0.25
B34: Capital discipline | C34: 0.15
B35: Carbon intensity | C35: 0.1
B36: Production growth | C36: 0.05 | D36: Lowest of the five priorities, so production size is a tie-breaker at most, never a reason to override a hard constraint
B38: 3. What doesn't add up for Puma
B39: ="1. Puma spends $"&TEXT(E5,"0")&"B over "&'Puma DCF'!D11&" years and earns nothing until "&E6&". Bison spends $"&TEXT(C5,"0")&"B and starts earning in "&C6&"." -> 1. Puma spends $15B over 5 years and earns nothing until 2032. Bison spends $2B and starts earning in 2028.
B40: ="2. Net debt/EBITDA climbs to "&TEXT(E14,"0.00")&"x in "&E15&" against a "&TEXT('WACC & Inputs'!C9,"0.00")&"x ceiling and is above it for "&E16&" years (first in "&E17&")." -> 2. Net debt/EBITDA climbs to 2.09x in 2031 against a 1.75x ceiling and is above it for 4 years (first in 2028).
B41: ="3. At the worst point NorthStar would carry $"&TEXT(-E18/1000,"0.0")&"B more net debt than the ceiling allows. Bison's tightest year still has $"&TEXT(C18/1000,"0.0")&"B of room; Fennec's has $"&TEXT(D18/1000,"0.0")&"B." -> 3. At the worst point NorthStar would carry $6.1B more net debt than the ceiling allows. Bison's tightest year still has $1.8B of room; Fennec's has $1.3B.
B42: ="4. Puma has the biggest NPV ($"&TEXT(E10/1000,"0.0")&"B) but the lowest IRR ("&TEXT(E11,"0.0%")&" vs Bison "&TEXT(C11,"0.0%")&"): the value comes from size and "&'Puma DCF'!D9&" years of production, not from returns on capital." -> 4. Puma has the biggest NPV ($5.6B) but the lowest IRR (15.5% vs Bison 21.3%): the value comes from size and 25 years of production, not from returns on capital.
B43: ="5. Size does not rescue it: Puma's "&TEXT(E7,"0")&" MBOED peak is "&TEXT(E7/C7,"0.0")&"x Bison's, but the case weights production growth at 5% and treats leverage as a hard disqualifier." -> 5. Size does not rescue it: Puma's 300 MBOED peak is 4.0x Bison's, but the case weights production growth at 5% and treats leverage as a hard disqualifier.
B44: 6. The case says it directly: a project that cannot clear both constraints "cannot be recommended, no matter how high its standalone value" (case p.6-7).
...

Sheet WACC & Inputs
B1: WACC & Inputs
B2: Green = linked to a case exhibit · Blue = typed input (source noted) · Yellow = switch your team can flip · Black = formula
B4: Inputs taken from the case text / exhibit notes
B5: Internal carbon price ($ per tonne CO2e) | C5: 75 | D5: Case p.2 & p.5: "$75 per metric ton". Valuation only: not tax-deductible, not in leverage test.
B6: Gas conversion (mcf per boe) | C6: 6 | D6: Exhibit 8 note 2: 6,000 cubic feet = 1 boe
B7: MMBtu per mcf | C7: 1.028 | D7: Exhibit 8 note 3: 1 MMSCF = 1,028 MMBtu
B8: Days per year | C8: 365 | D8: Simplification (no leap years)
B9: Leverage ceiling (Net debt / Adj. EBITDA) | C9: =VALUE(SUBSTITUTE('Exhibit 12'!D9,"x","")) -> 1.75 | D9: Exhibit 12 (stored there as text "1.75x")
B10: Country-risk method: 1 = equity-only, 2 = whole-WACC | C10: 1 | D10: Exhibit 4 says "unweighted" without saying where it goes. Flip to 2 to see the other reading.
B11: Corporate tax rate | C11: ='Exhibit 1'!C6 -> 0.21 | D11: Exhibit 1
B14: Comparable firm (Exhibit 3) | C14: Levered beta | D14: Total debt ($000) | E14: Market cap ($000) | F14: Debt / equity | G14: Unlevered beta | H14: Include? (1/0) | I14: Note
B15: ='Exhibit 3'!B6 -> Company A | C15: ='Exhibit 3'!N6 -> 1.45 | D15: ='Exhibit 3'!F6 -> 58786280 | E15: ='Exhibit 3'!E6 -> 81285877 | F15: =D15/E15 -> 0.72320411 | G15: =C15/(1+(1-$C$11)*F15) -> 0.92278443 | H15: 1
B16: ='Exhibit 3'!B7 -> Company B | C16: ='Exhibit 3'!N7 -> 1.14 | D16: ='Exhibit 3'!F7 -> 38286344 | E16: ='Exhibit 3'!E7 -> 96481166 | F16: =D16/E16 -> 0.39682713 | G16: =C16/(1+(1-$C$11)*F16) -> 0.8679145 | H16: 1
B17: ='Exhibit 3'!B8 -> Company C | C17: ='Exhibit 3'!N8 -> 1.77 | D17: ='Exhibit 3'!F8 -> 68437320 | E17: ='Exhibit 3'!E8 -> 1.4070521e+08 | F17: =D17/E17 -> 0.48638797 | G17: =C17/(1+(1-$C$11)*F17) -> 1.278674 | H17: 1
B18: ='Exhibit 3'!B9 -> Company D | C18: ='Exhibit 3'!N9 -> 1.16 | D18: ='Exhibit 3'!F9 -> 37564875 | E18: ='Exhibit 3'!E9 -> 1.1464793e+08 | F18: =D18/E18 -> 0.3276542 | G18: =C18/(1+(1-$C$11)*F18) -> 0.92147828 | H18: 1
B19: ='Exhibit 3'!B10 -> Company E | C19: ='Exhibit 3'!N10 -> 1.25 | D19: ='Exhibit 3'!F10 -> 45894882 | E19: ='Exhibit 3'!E10 -> 43600829 | F19: =D19/E19 -> 1.0526149 | G19: =C19/(1+(1-$C$11)*F19) -> 0.68247618 | H19: 1
B20: ='Exhibit 3'!B11 -> Company F | C20: ='Exhibit 3'!N11 -> 0.79 | D20: ='Exhibit 3'!F11 -> 12118484 | E20: ='Exhibit 3'!E11 -> 5758257.5 | F20: =D20/E20 -> 2.1045401 | G20: =C20/(1+(1-$C$11)*F20) -> 0.29670395 | H20: 1
B21: ='Exhibit 3'!B12 -> Company G | C21: ='Exhibit 3'!N12 -> 0.92 | D21: ='Exhibit 3'!F12 -> 12855538 | E21: ='Exhibit 3'!E12 -> 70196096 | F21: =D21/E21 -> 0.18313751 | G21: =C21/(1+(1-$C$11)*F21) -> 0.80371903 | H21: 1
B22: ='Exhibit 3'!B13 -> Company H | C22: ='Exhibit 3'!N13 -> 1.26 | D22: ='Exhibit 3'!F13 -> 13498324 | E22: ='Exhibit 3'!E13 -> 45325061 | F22: =D22/E22 -> 0.29781149 | G22: =C22/(1+(1-$C$11)*F22) -> 1.020019 | H22: 1
B23: ='Exhibit 3'!B14 -> Company I | C23: ='Exhibit 3'!N14 -> 1.42 | D23: ='Exhibit 3'!F14 -> 30183120 | E23: ='Exhibit 3'!E14 -> 3605707.8 | F23: =D23/E23 -> 8.3709278 | G23: =C23/(1+(1-$C$11)*F23) -> 0.18652224 | H23: 0 | I23: Excluded: debt/equity so high that the unlevering formula is unreliable
B24: ='Exhibit 3'!B15 -> Company J | C24: ='Exhibit 3'!N15 -> 0.71 | D24: ='Exhibit 3'!F15 -> 10927581 | E24: ='Exhibit 3'!E15 -> 2447214.7 | F24: =D24/E24 -> 4.4653136 | G24: =C24/(1+(1-$C$11)*F24) -> 0.15681605 | H24: 0 | I24: Excluded: debt/equity so high that the unlevering formula is unreliable
B25: ='Exhibit 3'!B16 -> Company K | C25: ='Exhibit 3'!N16 -> 1.42 | D25: ='Exhibit 3'!F16 -> 45461220 | E25: ='Exhibit 3'!E16 -> 1.2303114e+08 | F25: =D25/E25 -> 0.36950986 | G25: =C25/(1+(1-$C$11)*F25) -> 1.0991454 | H25: 1
B26: Exhibit 3 note: "MUSD = thousands USD" - so these columns are in thousands of dollars.
B27: Average unlevered beta (included comps) | G27: =SUMPRODUCT(G15:G25,H15:H25)/SUM(H15:H25) -> 0.87699053
B30: NorthStar capital structure and base WACC
B31: Equity market value ($MM) | C31: ='Exhibit 2'!E80*'Exhibit 2'!E81 -> 51842 | D31: Stock price x shares, 2026 (Exhibit 2)
B32: Total debt ($MM) | C32: ='Exhibit 2'!E41+'Exhibit 2'!E44 -> 26764 | D32: Current + long-term debt, 2026 (Exhibit 2)
B33: Debt / equity | C33: =C32/C31 -> 0.51626095
B34: Debt / (debt + equity) | C34: =C32/(C32+C31) -> 0.34048291
B35: Equity / (debt + equity) | C35: =1-C34 -> 0.65951709
B36: Relevered beta | C36: =G27*(1+(1-C11)*C33) -> 1.2346677 | D36: Unlevered average re-levered at NorthStar D/E
B37: Risk-free rate | C37: ='Exhibit 1'!C7 -> 0.04 | D37: Exhibit 1
B38: Equity risk premium | C38: ='Exhibit 1'!C8 -> 0.055 | D38: Exhibit 1
B39: Cost of equity (no country risk) | C39: =C37+C36*C38 -> 0.10790673 | D39: CAPM
B40: Pre-tax cost of debt | C40: ='Exhibit 2'!E74 -> 0.0566 | D40: NorthStar 2026 interest rate (Exhibit 2); same rate used for all projects
B41: After-tax cost of debt | C41: =C40*(1-C11) -> 0.044714
B42: Base WACC (Frontera, no country risk) | C42: =C35*C39+C34*C41 -> 0.086390682
B45: Project | C45: Country risk premium (Exhibit 4) | D45: Cost of equity incl. premium | E45: WACC: equity-only | F45: WACC: whole-WACC | G45: WACC USED (per switch)
B46: Bison (Frontera) | C46: ='Exhibit 4'!C5 -> 0 | D46: =$C$39+C46 -> 0.10790673 | E46: =$C$35*D46+$C$34*$C$41 -> 0.086390682 | F46: =$C$42+C46 -> 0.086390682 | G46: =CHOOSE($C$10,E46,F46) -> 0.086390682
B47: Fennec (Tassili) | C47: ='Exhibit 4'!C7 -> 0.06 | D47: =$C$39+C47 -> 0.16790673 | E47: =$C$35*D47+$C$34*$C$41 -> 0.12596171 | F47: =$C$42+C47 -> 0.14639068 | G47: =CHOOSE($C$10,E47,F47) -> 0.12596171
...

Sheet Bison DCF
B1: Project Bison: DCF, IRR and leverage check
B2: $ in millions unless stated. Costs shown as negatives. Green = linked to exhibits, black = formula. Carbon is deducted for valuation only (rows 41-42), never in the leverage test.
B3: Inputs (linked)
B4: Development cost ($MM) | D4: ='Exhibit 1'!C11*1000 -> 2000
B5: Production royalty and government take (% of revenue) | D5: ='Exhibit 1'!C12 -> 0.15
B6: Direct operating expense ($/boe) | D6: ='Exhibit 1'!C13 -> 15
B7: Overhead expense ($/boe) | D7: ='Exhibit 1'!C14 -> 2
B8: Midstream expense ($/boe) | D8: ='Exhibit 1'!C16 -> 2
B9: Depreciation / producing life (years) | D9: ='Exhibit 1'!C15 -> 10
B10: Undiscounted decommissioning ($MM, final year) | D10: ='Exhibit 1'!C17 -> 200
B11: Development years (time to production) | D11: ='Exhibit 1'!C18 -> 1
B12: Carbon intensity (kg CO2e/boe) | D12: ='Exhibit 10'!D5 -> 16
B13: Corporate tax rate | D13: ='WACC & Inputs'!$C$11 -> 0.21
B14: WACC used | D14: ='WACC & Inputs'!G46 -> 0.086390682
B16: Year | D16: 2027 | E16: =D16+1 -> 2028 | F16: =E16+1 -> 2029 | G16: =F16+1 -> 2030 | H16: =G16+1 -> 2031 | I16: =H16+1 -> 2032 | J16: =I16+1 -> 2033 | K16: =J16+1 -> 2034 | L16: =K16+1 -> 2035 | ... N16: =M16+1 -> 2037
B17: Oil-equivalent production (MBOED) | D17: ='Exhibit 5'!D5 -> 0 | E17: ='Exhibit 5'!E5 -> 75 | F17: ='Exhibit 5'!F5 -> 75 | G17: ='Exhibit 5'!G5 -> 75 | H17: ='Exhibit 5'!H5 -> 74.86 | I17: ='Exhibit 5'!I5 -> 74.93 | J17: ='Exhibit 5'!J5 -> 74.82 | K17: ='Exhibit 5'!K5 -> 74.64 | ... N17: ='Exhibit 5'!N5 -> 74.4
B18: Annual volume (MM boe) | D18: =D17*1000*'WACC & Inputs'!$C$8/1000000 -> 0 | E18: =E17*1000*'WACC & Inputs'!$C$8/1000000 -> 27.375 | F18: =F17*1000*'WACC & Inputs'!$C$8/1000000 -> 27.375 | G18: =G17*1000*'WACC & Inputs'!$C$8/1000000 -> 27.375 | H18: =H17*1000*'WACC & Inputs'!$C$8/1000000 -> 27.3239 | I18: =I17*1000*'WACC & Inputs'!$C$8/1000000 -> 27.34945 | J18: =J17*1000*'WACC & Inputs'!$C$8/1000000 -> 27.3093 | K18: =K17*1000*'WACC & Inputs'!$C$8/1000000 -> 27.2436 | ... N18: =N17*1000*'WACC & Inputs'!$C$8/1000000 -> 27.156
B19: Crude share of boe | D19: ='Exhibit 8'!E5 -> 0 | E19: ='Exhibit 8'!F5 -> 0.59 | F19: ='Exhibit 8'!G5 -> 0.585 | G19: ='Exhibit 8'!H5 -> 0.58 | H19: ='Exhibit 8'!I5 -> 0.575 | I19: ='Exhibit 8'!J5 -> 0.57 | J19: ='Exhibit 8'!K5 -> 0.565 | K19: ='Exhibit 8'!L5 -> 0.56 | ... N19: ='Exhibit 8'!O5 -> 0.53
B20: Natural gas share of boe | D20: ='Exhibit 8'!E6 -> 0 | E20: ='Exhibit 8'!F6 -> 0.328 | F20: ='Exhibit 8'!G6 -> 0.332 | G20: ='Exhibit 8'!H6 -> 0.336 | H20: ='Exhibit 8'!I6 -> 0.34 | I20: ='Exhibit 8'!J6 -> 0.344 | J20: ='Exhibit 8'!K6 -> 0.348 | K20: ='Exhibit 8'!L6 -> 0.352 | ... N20: ='Exhibit 8'!O6 -> 0.376
B21: NGL share of boe | D21: ='Exhibit 8'!E7 -> 0 | E21: ='Exhibit 8'!F7 -> 0.082 | F21: ='Exhibit 8'!G7 -> 0.083 | G21: ='Exhibit 8'!H7 -> 0.084 | H21: ='Exhibit 8'!I7 -> 0.085 | I21: ='Exhibit 8'!J7 -> 0.086 | J21: ='Exhibit 8'!K7 -> 0.087 | K21: ='Exhibit 8'!L7 -> 0.088 | ... N21: ='Exhibit 8'!O7 -> 0.094
B22: Crude price ($/bbl) | D22: ='Exhibit 9'!F5 -> 80.98 | E22: ='Exhibit 9'!G5 -> 72.38 | F22: ='Exhibit 9'!H5 -> 69.47 | G22: ='Exhibit 9'!I5 -> 69.47 | H22: ='Exhibit 9'!J5 -> 69.47 | I22: ='Exhibit 9'!K5 -> 69.47 | J22: ='Exhibit 9'!L5 -> 69.47 | K22: ='Exhibit 9'!M5 -> 69.47 | ... N22: ='Exhibit 9'!P5 -> 69.47
B23: Gas price ($/MMBtu) | D23: ='Exhibit 9'!F6 -> 3.06 | E23: ='Exhibit 9'!G6 -> 3.38 | F23: ='Exhibit 9'!H6 -> 3.38 | G23: ='Exhibit 9'!I6 -> 3.38 | H23: ='Exhibit 9'!J6 -> 3.38 | I23: ='Exhibit 9'!K6 -> 3.38 | J23: ='Exhibit 9'!L6 -> 3.38 | K23: ='Exhibit 9'!M6 -> 3.38 | ... N23: ='Exhibit 9'!P6 -> 3.38
B24: NGL price ($/bbl) | D24: ='Exhibit 9'!F7 -> 28.34 | E24: ='Exhibit 9'!G7 -> 25.33 | F24: ='Exhibit 9'!H7 -> 24.31 | G24: ='Exhibit 9'!I7 -> 24.31 | H24: ='Exhibit 9'!J7 -> 24.31 | I24: ='Exhibit 9'!K7 -> 24.31 | J24: ='Exhibit 9'!L7 -> 24.31 | K24: ='Exhibit 9'!M7 -> 24.31 | ... N24: ='Exhibit 9'!P7 -> 24.31
B25: Gas price converted ($/boe) | D25: =D23*'WACC & Inputs'!$C$6*'WACC & Inputs'!$C$7 -> 18.87408 | E25: =E23*'WACC & Inputs'!$C$6*'WACC & Inputs'!$C$7 -> 20.84784 | F25: =F23*'WACC & Inputs'!$C$6*'WACC & Inputs'!$C$7 -> 20.84784 | G25: =G23*'WACC & Inputs'!$C$6*'WACC & Inputs'!$C$7 -> 20.84784 | H25: =H23*'WACC & Inputs'!$C$6*'WACC & Inputs'!$C$7 -> 20.84784 | I25: =I23*'WACC & Inputs'!$C$6*'WACC & Inputs'!$C$7 -> 20.84784 | J25: =J23*'WACC & Inputs'!$C$6*'WACC & Inputs'!$C$7 -> 20.84784 | K25: =K23*'WACC & Inputs'!$C$6*'WACC & Inputs'!$C$7 -> 20.84784 | ... N25: =N23*'WACC & Inputs'!$C$6*'WACC & Inputs'!$C$7 -> 20.84784
B26: Crude revenue | D26: =D18*D19*D22 -> 0 | E26: =E18*E19*E22 -> 1169.0275 | F26: =F18*F19*F22 -> 1112.5186 | G26: =G18*G19*G22 -> 1103.0099 | H26: =H18*H19*H22 -> 1091.46 | I26: =I18*I19*I22 -> 1082.9808 | J26: =J18*J19*J22 -> 1071.905 | K26: =K18*K19*K22 -> 1059.8632 | ... N26: =N18*N19*N22 -> 999.85948
B27: Gas revenue | D27: =D18*D20*D25 -> 0 | E27: =E18*E20*E25 -> 187.19276 | F27: =F18*F20*F25 -> 189.47559 | G27: =G18*G20*G25 -> 191.75843 | H27: =H18*H20*H25 -> 193.67906 | I27: =I18*I20*I25 -> 196.14087 | J27: =J18*J20*J25 -> 198.13029 | K27: =K18*K20*K25 -> 199.92552 | ... N27: =N18*N20*N25 -> 212.87012
B28: NGL revenue | D28: =D18*D21*D24 -> 0 | E28: =E18*E21*E24 -> 56.859518 | F28: =F18*F21*F24 -> 55.235359 | G28: =G18*G21*G24 -> 55.900845 | H28: =H18*H21*H24 -> 56.460741 | I28: =I18*I21*I24 -> 57.178401 | J28: =J18*J21*J24 -> 57.75835 | K28: =K18*K21*K24 -> 58.281689 | ... N28: =N18*N21*N24 -> 62.055262
B29: Total revenue | D29: =SUM(D26:D28) -> 0 | E29: =SUM(E26:E28) -> 1413.0797 | F29: =SUM(F26:F28) -> 1357.2296 | G29: =SUM(G26:G28) -> 1350.6692 | H29: =SUM(H26:H28) -> 1341.5998 | I29: =SUM(I26:I28) -> 1336.3001 | J29: =SUM(J26:J28) -> 1327.7937 | K29: =SUM(K26:K28) -> 1318.0704 | ... N29: =SUM(N26:N28) -> 1274.7849
B30: Less: royalty and government take | D30: =-D29*$D$5 -> 0 | E30: =-E29*$D$5 -> -211.96196 | F30: =-F29*$D$5 -> -203.58444 | G30: =-G29*$D$5 -> -202.60038 | H30: =-H29*$D$5 -> -201.23997 | I30: =-I29*$D$5 -> -200.44501 | J30: =-J29*$D$5 -> -199.16905 | K30: =-K29*$D$5 -> -197.71056 | ... N30: =-N29*$D$5 -> -191.21773
B31: Less: direct opex | D31: =-D18*$D$6 -> 0 | E31: =-E18*$D$6 -> -410.625 | F31: =-F18*$D$6 -> -410.625 | G31: =-G18*$D$6 -> -410.625 | H31: =-H18*$D$6 -> -409.8585 | I31: =-I18*$D$6 -> -410.24175 | J31: =-J18*$D$6 -> -409.6395 | K31: =-K18*$D$6 -> -408.654 | ... N31: =-N18*$D$6 -> -407.34
B32: Less: overhead | D32: =-D18*$D$7 -> 0 | E32: =-E18*$D$7 -> -54.75 | F32: =-F18*$D$7 -> -54.75 | G32: =-G18*$D$7 -> -54.75 | H32: =-H18*$D$7 -> -54.6478 | I32: =-I18*$D$7 -> -54.6989 | J32: =-J18*$D$7 -> -54.6186 | K32: =-K18*$D$7 -> -54.4872 | ... N32: =-N18*$D$7 -> -54.312
B33: Less: midstream | D33: =-D18*$D$8 -> 0 | E33: =-E18*$D$8 -> -54.75 | F33: =-F18*$D$8 -> -54.75 | G33: =-G18*$D$8 -> -54.75 | H33: =-H18*$D$8 -> -54.6478 | I33: =-I18*$D$8 -> -54.6989 | J33: =-J18*$D$8 -> -54.6186 | K33: =-K18*$D$8 -> -54.4872 | ... N33: =-N18*$D$8 -> -54.312
B34: EBITDA (project) | D34: =SUM(D29:D33) -> 0 | E34: =SUM(E29:E33) -> 680.99279 | F34: =SUM(F29:F33) -> 633.52015 | G34: =SUM(G29:G33) -> 627.94382 | H34: =SUM(H29:H33) -> 621.20575 | I34: =SUM(I29:I33) -> 616.2155 | J34: =SUM(J29:J33) -> 609.74793 | K34: =SUM(K29:K33) -> 602.73146 | ... N34: =SUM(N29:N33) -> 567.60313
B35: Less: depreciation (straight line from first production year) | D35: =-IF(D17>0,$D$4/$D$9,0) -> 0 | E35: =-IF(E17>0,$D$4/$D$9,0) -> -200 | F35: =-IF(F17>0,$D$4/$D$9,0) -> -200 | G35: =-IF(G17>0,$D$4/$D$9,0) -> -200 | H35: =-IF(H17>0,$D$4/$D$9,0) -> -200 | I35: =-IF(I17>0,$D$4/$D$9,0) -> -200 | J35: =-IF(J17>0,$D$4/$D$9,0) -> -200 | K35: =-IF(K17>0,$D$4/$D$9,0) -> -200 | ... N35: =-IF(N17>0,$D$4/$D$9,0) -> -200
B36: Taxable income | D36: =D34+D35 -> 0 | E36: =E34+E35 -> 480.99279 | F36: =F34+F35 -> 433.52015 | G36: =G34+G35 -> 427.94382 | H36: =H34+H35 -> 421.20575 | I36: =I34+I35 -> 416.2155 | J36: =J34+J35 -> 409.74793 | K36: =K34+K35 -> 402.73146 | ... N36: =N34+N35 -> 367.60313
B37: Less: income tax @ 21% | D37: =-$D$13*D36 -> 0 | E37: =-$D$13*E36 -> -101.00848 | F37: =-$D$13*F36 -> -91.039231 | G37: =-$D$13*G36 -> -89.868203 | H37: =-$D$13*H36 -> -88.453206 | I37: =-$D$13*I36 -> -87.405255 | J37: =-$D$13*J36 -> -86.047066 | K37: =-$D$13*K36 -> -84.573607 | ... N37: =-$D$13*N36 -> -77.196658
B38: Less: development capex (split evenly over development years) | D38: =-IF(D$16<2027+$D$11,$D$4/$D$11,0) -> -2000 | E38: =-IF(E$16<2027+$D$11,$D$4/$D$11,0) -> 0 | F38: =-IF(F$16<2027+$D$11,$D$4/$D$11,0) -> 0 | G38: =-IF(G$16<2027+$D$11,$D$4/$D$11,0) -> 0 | H38: =-IF(H$16<2027+$D$11,$D$4/$D$11,0) -> 0 | I38: =-IF(I$16<2027+$D$11,$D$4/$D$11,0) -> 0 | J38: =-IF(J$16<2027+$D$11,$D$4/$D$11,0) -> 0 | K38: =-IF(K$16<2027+$D$11,$D$4/$D$11,0) -> 0 | ... N38: =-IF(N$16<2027+$D$11,$D$4/$D$11,0) -> 0
B39: Less: decommissioning (final year, not deductible) | D39: =-IF(D$16=2027+$D$11+$D$9-1,$D$10,0) -> 0 | E39: =-IF(E$16=2027+$D$11+$D$9-1,$D$10,0) -> 0 | F39: =-IF(F$16=2027+$D$11+$D$9-1,$D$10,0) -> 0 | G39: =-IF(G$16=2027+$D$11+$D$9-1,$D$10,0) -> 0 | H39: =-IF(H$16=2027+$D$11+$D$9-1,$D$10,0) -> 0 | I39: =-IF(I$16=2027+$D$11+$D$9-1,$D$10,0) -> 0 | J39: =-IF(J$16=2027+$D$11+$D$9-1,$D$10,0) -> 0 | K39: =-IF(K$16=2027+$D$11+$D$9-1,$D$10,0) -> 0 | ... N39: =-IF(N$16=2027+$D$11+$D$9-1,$D$10,0) -> -200
B40: Unlevered free cash flow (used in leverage test) | D40: =D34+D37+D38+D39 -> -2000 | E40: =E34+E37+E38+E39 -> 579.9843 | F40: =F34+F37+F38+F39 -> 542.48092 | G40: =G34+G37+G38+G39 -> 538.07562 | H40: =H34+H37+H38+H39 -> 532.75254 | I40: =I34+I37+I38+I39 -> 528.81025 | J40: =J34+J37+J38+J39 -> 523.70087 | K40: =K34+K37+K38+K39 -> 518.15785 | ... N40: =N34+N37+N38+N39 -> 290.40648
B41: Less: carbon cost @ $75/t (valuation only) | D41: =-D18*$D$12*'WACC & Inputs'!$C$5/1000 -> 0 | E41: =-E18*$D$12*'WACC & Inputs'!$C$5/1000 -> -32.85 | F41: =-F18*$D$12*'WACC & Inputs'!$C$5/1000 -> -32.85 | G41: =-G18*$D$12*'WACC & Inputs'!$C$5/1000 -> -32.85 | H41: =-H18*$D$12*'WACC & Inputs'!$C$5/1000 -> -32.78868 | I41: =-I18*$D$12*'WACC & Inputs'!$C$5/1000 -> -32.81934 | J41: =-J18*$D$12*'WACC & Inputs'!$C$5/1000 -> -32.77116 | K41: =-K18*$D$12*'WACC & Inputs'!$C$5/1000 -> -32.69232 | ... N41: =-N18*$D$12*'WACC & Inputs'!$C$5/1000 -> -32.5872
...

Sheet Fennec DCF
B1: Project Fennec: DCF, IRR and leverage check
B2: $ in millions unless stated. Costs shown as negatives. Green = linked to exhibits, black = formula. Carbon is deducted for valuation only (rows 41-42), never in the leverage test.
B3: Inputs (linked)
B4: Development cost ($MM) | D4: ='Exhibit 1'!C22*1000 -> 5000
B5: Production royalty and government take (% of revenue) | D5: ='Exhibit 1'!C23 -> 0.3
B6: Direct operating expense ($/boe) | D6: ='Exhibit 1'!C24 -> 14
B7: Overhead expense ($/boe) | D7: ='Exhibit 1'!C25 -> 3.5
B8: Midstream expense ($/boe) | D8: ='Exhibit 1'!C27 -> 7
B9: Depreciation / producing life (years) | D9: ='Exhibit 1'!C26 -> 15
B10: Undiscounted decommissioning ($MM, final year) | D10: ='Exhibit 1'!C28 -> 350
B11: Development years (time to production) | D11: ='Exhibit 1'!C29 -> 3
B12: Carbon intensity (kg CO2e/boe) | D12: ='Exhibit 10'!E5 -> 19
B13: Corporate tax rate | D13: ='WACC & Inputs'!$C$11 -> 0.21
B14: WACC used | D14: ='WACC & Inputs'!G47 -> 0.12596171
B16: Year | D16: 2027 | E16: =D16+1 -> 2028 | F16: =E16+1 -> 2029 | G16: =F16+1 -> 2030 | H16: =G16+1 -> 2031 | I16: =H16+1 -> 2032 | J16: =I16+1 -> 2033 | K16: =J16+1 -> 2034 | L16: =K16+1 -> 2035 | ... U16: =T16+1 -> 2044
B17: Oil-equivalent production (MBOED) | D17: ='Exhibit 6'!D5 -> 0 | E17: ='Exhibit 6'!E5 -> 0 | F17: ='Exhibit 6'!F5 -> 0 | G17: ='Exhibit 6'!G5 -> 150 | H17: ='Exhibit 6'!H5 -> 150 | I17: ='Exhibit 6'!I5 -> 150 | J17: ='Exhibit 6'!J5 -> 150 | K17: ='Exhibit 6'!K5 -> 150 | ... U17: ='Exhibit 6'!U5 -> 27.61
B18: Annual volume (MM boe) | D18: =D17*1000*'WACC & Inputs'!$C$8/1000000 -> 0 | E18: =E17*1000*'WACC & Inputs'!$C$8/1000000 -> 0 | F18: =F17*1000*'WACC & Inputs'!$C$8/1000000 -> 0 | G18: =G17*1000*'WACC & Inputs'!$C$8/1000000 -> 54.75 | H18: =H17*1000*'WACC & Inputs'!$C$8/1000000 -> 54.75 | I18: =I17*1000*'WACC & Inputs'!$C$8/1000000 -> 54.75 | J18: =J17*1000*'WACC & Inputs'!$C$8/1000000 -> 54.75 | K18: =K17*1000*'WACC & Inputs'!$C$8/1000000 -> 54.75 | ... U18: =U17*1000*'WACC & Inputs'!$C$8/1000000 -> 10.07765
B19: Crude share of boe | D19: ='Exhibit 8'!E8 -> 0 | E19: ='Exhibit 8'!F8 -> 0 | F19: ='Exhibit 8'!G8 -> 0 | G19: ='Exhibit 8'!H8 -> 0.35 | H19: ='Exhibit 8'!I8 -> 0.34 | I19: ='Exhibit 8'!J8 -> 0.33 | J19: ='Exhibit 8'!K8 -> 0.32 | K19: ='Exhibit 8'!L8 -> 0.31 | ... U19: ='Exhibit 8'!V8 -> 0.21
B20: Natural gas share of boe | D20: ='Exhibit 8'!E9 -> 0 | E20: ='Exhibit 8'!F9 -> 0 | F20: ='Exhibit 8'!G9 -> 0 | G20: ='Exhibit 8'!H9 -> 0.6125 | H20: ='Exhibit 8'!I9 -> 0.6175 | I20: ='Exhibit 8'!J9 -> 0.6225 | J20: ='Exhibit 8'!K9 -> 0.6275 | K20: ='Exhibit 8'!L9 -> 0.6325 | ... U20: ='Exhibit 8'!V9 -> 0.6825
B21: NGL share of boe | D21: ='Exhibit 8'!E10 -> 0 | E21: ='Exhibit 8'!F10 -> 0 | F21: ='Exhibit 8'!G10 -> 0 | G21: ='Exhibit 8'!H10 -> 0.0375 | H21: ='Exhibit 8'!I10 -> 0.0425 | I21: ='Exhibit 8'!J10 -> 0.0475 | J21: ='Exhibit 8'!K10 -> 0.0525 | K21: ='Exhibit 8'!L10 -> 0.0575 | ... U21: ='Exhibit 8'!V10 -> 0.1075
B22: Crude price ($/bbl) | D22: ='Exhibit 9'!F8 -> 86.92 | E22: ='Exhibit 9'!G8 -> 77.63 | F22: ='Exhibit 9'!H8 -> 74.37 | G22: ='Exhibit 9'!I8 -> 74.37 | H22: ='Exhibit 9'!J8 -> 74.37 | I22: ='Exhibit 9'!K8 -> 74.37 | J22: ='Exhibit 9'!L8 -> 74.37 | K22: ='Exhibit 9'!M8 -> 74.37 | ... U22: ='Exhibit 9'!W8 -> 74.37
B23: Gas price ($/MMBtu) | D23: ='Exhibit 9'!F9 -> 20.25 | E23: ='Exhibit 9'!G9 -> 14.53 | F23: ='Exhibit 9'!H9 -> 14.53 | G23: ='Exhibit 9'!I9 -> 14.53 | H23: ='Exhibit 9'!J9 -> 14.53 | I23: ='Exhibit 9'!K9 -> 14.53 | J23: ='Exhibit 9'!L9 -> 14.53 | K23: ='Exhibit 9'!M9 -> 14.53 | ... U23: ='Exhibit 9'!W9 -> 14.53
B24: NGL price ($/bbl) | D24: ='Exhibit 9'!F10 -> 31.34 | E24: ='Exhibit 9'!G10 -> 28.33 | F24: ='Exhibit 9'!H10 -> 27.31 | G24: ='Exhibit 9'!I10 -> 27.31 | H24: ='Exhibit 9'!J10 -> 27.31 | I24: ='Exhibit 9'!K10 -> 27.31 | J24: ='Exhibit 9'!L10 -> 27.31 | K24: ='Exhibit 9'!M10 -> 27.31 | ... U24: ='Exhibit 9'!W10 -> 27.31
B25: Gas price converted ($/boe) | D25: =D23*'WACC & Inputs'!$C$6*'WACC & Inputs'!$C$7 -> 124.902 | E25: =E23*'WACC & Inputs'!$C$6*'WACC & Inputs'!$C$7 -> 89.62104 | F25: =F23*'WACC & Inputs'!$C$6*'WACC & Inputs'!$C$7 -> 89.62104 | G25: =G23*'WACC & Inputs'!$C$6*'WACC & Inputs'!$C$7 -> 89.62104 | H25: =H23*'WACC & Inputs'!$C$6*'WACC & Inputs'!$C$7 -> 89.62104 | I25: =I23*'WACC & Inputs'!$C$6*'WACC & Inputs'!$C$7 -> 89.62104 | J25: =J23*'WACC & Inputs'!$C$6*'WACC & Inputs'!$C$7 -> 89.62104 | K25: =K23*'WACC & Inputs'!$C$6*'WACC & Inputs'!$C$7 -> 89.62104 | ... U25: =U23*'WACC & Inputs'!$C$6*'WACC & Inputs'!$C$7 -> 89.62104
B26: Crude revenue | D26: =D18*D19*D22 -> 0 | E26: =E18*E19*E22 -> 0 | F26: =F18*F19*F22 -> 0 | G26: =G18*G19*G22 -> 1425.1151 | H26: =H18*H19*H22 -> 1384.3976 | I26: =I18*I19*I22 -> 1343.68 | J26: =J18*J19*J22 -> 1302.9624 | K26: =K18*K19*K22 -> 1262.2448 | ... U26: =U18*U19*U22 -> 157.38971
B27: Gas revenue | D27: =D18*D20*D25 -> 0 | E27: =E18*E20*E25 -> 0 | F27: =F18*F20*F25 -> 0 | G27: =G18*G20*G25 -> 3005.3856 | H27: =H18*H20*H25 -> 3029.9193 | I27: =I18*I20*I25 -> 3054.4531 | J27: =J18*J20*J25 -> 3078.9868 | K27: =K18*K20*K25 -> 3103.5206 | ... U27: =U18*U20*U25 -> 616.41317
B28: NGL revenue | D28: =D18*D21*D24 -> 0 | E28: =E18*E21*E24 -> 0 | F28: =F18*F21*F24 -> 0 | G28: =G18*G21*G24 -> 56.070844 | H28: =H18*H21*H24 -> 63.546956 | I28: =I18*I21*I24 -> 71.023069 | J28: =J18*J21*J24 -> 78.499181 | K28: =K18*K21*K24 -> 85.975294 | ... U28: =U18*U21*U24 -> 29.586217
B29: Total revenue | D29: =SUM(D26:D28) -> 0 | E29: =SUM(E26:E28) -> 0 | F29: =SUM(F26:F28) -> 0 | G29: =SUM(G26:G28) -> 4486.5715 | H29: =SUM(H26:H28) -> 4477.8638 | I29: =SUM(I26:I28) -> 4469.1561 | J29: =SUM(J26:J28) -> 4460.4484 | K29: =SUM(K26:K28) -> 4451.7407 | ... U29: =SUM(U26:U28) -> 803.3891
B30: Less: royalty and government take | D30: =-D29*$D$5 -> 0 | E30: =-E29*$D$5 -> 0 | F30: =-F29*$D$5 -> 0 | G30: =-G29*$D$5 -> -1345.9715 | H30: =-H29*$D$5 -> -1343.3591 | I30: =-I29*$D$5 -> -1340.7468 | J30: =-J29*$D$5 -> -1338.1345 | K30: =-K29*$D$5 -> -1335.5222 | ... U30: =-U29*$D$5 -> -241.01673
B31: Less: direct opex | D31: =-D18*$D$6 -> 0 | E31: =-E18*$D$6 -> 0 | F31: =-F18*$D$6 -> 0 | G31: =-G18*$D$6 -> -766.5 | H31: =-H18*$D$6 -> -766.5 | I31: =-I18*$D$6 -> -766.5 | J31: =-J18*$D$6 -> -766.5 | K31: =-K18*$D$6 -> -766.5 | ... U31: =-U18*$D$6 -> -141.0871
B32: Less: overhead | D32: =-D18*$D$7 -> 0 | E32: =-E18*$D$7 -> 0 | F32: =-F18*$D$7 -> 0 | G32: =-G18*$D$7 -> -191.625 | H32: =-H18*$D$7 -> -191.625 | I32: =-I18*$D$7 -> -191.625 | J32: =-J18*$D$7 -> -191.625 | K32: =-K18*$D$7 -> -191.625 | ... U32: =-U18*$D$7 -> -35.271775
B33: Less: midstream | D33: =-D18*$D$8 -> 0 | E33: =-E18*$D$8 -> 0 | F33: =-F18*$D$8 -> 0 | G33: =-G18*$D$8 -> -383.25 | H33: =-H18*$D$8 -> -383.25 | I33: =-I18*$D$8 -> -383.25 | J33: =-J18*$D$8 -> -383.25 | K33: =-K18*$D$8 -> -383.25 | ... U33: =-U18*$D$8 -> -70.54355
B34: EBITDA (project) | D34: =SUM(D29:D33) -> 0 | E34: =SUM(E29:E33) -> 0 | F34: =SUM(F29:F33) -> 0 | G34: =SUM(G29:G33) -> 1799.2251 | H34: =SUM(H29:H33) -> 1793.1297 | I34: =SUM(I29:I33) -> 1787.0343 | J34: =SUM(J29:J33) -> 1780.9389 | K34: =SUM(K29:K33) -> 1774.8435 | ... U34: =SUM(U29:U33) -> 315.46994
B35: Less: depreciation (straight line from first production year) | D35: =-IF(D17>0,$D$4/$D$9,0) -> 0 | E35: =-IF(E17>0,$D$4/$D$9,0) -> 0 | F35: =-IF(F17>0,$D$4/$D$9,0) -> 0 | G35: =-IF(G17>0,$D$4/$D$9,0) -> -333.33333 | H35: =-IF(H17>0,$D$4/$D$9,0) -> -333.33333 | I35: =-IF(I17>0,$D$4/$D$9,0) -> -333.33333 | J35: =-IF(J17>0,$D$4/$D$9,0) -> -333.33333 | K35: =-IF(K17>0,$D$4/$D$9,0) -> -333.33333 | ... U35: =-IF(U17>0,$D$4/$D$9,0) -> -333.33333
B36: Taxable income | D36: =D34+D35 -> 0 | E36: =E34+E35 -> 0 | F36: =F34+F35 -> 0 | G36: =G34+G35 -> 1465.8917 | H36: =H34+H35 -> 1459.7963 | I36: =I34+I35 -> 1453.701 | J36: =J34+J35 -> 1447.6056 | K36: =K34+K35 -> 1441.5102 | ... U36: =U34+U35 -> -17.86339
B37: Less: income tax @ 21% | D37: =-$D$13*D36 -> 0 | E37: =-$D$13*E36 -> 0 | F37: =-$D$13*F36 -> 0 | G37: =-$D$13*G36 -> -307.83727 | H37: =-$D$13*H36 -> -306.55723 | I37: =-$D$13*I36 -> -305.2772 | J37: =-$D$13*J36 -> -303.99717 | K37: =-$D$13*K36 -> -302.71714 | ... U37: =-$D$13*U36 -> 3.751312
B38: Less: development capex (split evenly over development years) | D38: =-IF(D$16<2027+$D$11,$D$4/$D$11,0) -> -1666.6667 | E38: =-IF(E$16<2027+$D$11,$D$4/$D$11,0) -> -1666.6667 | F38: =-IF(F$16<2027+$D$11,$D$4/$D$11,0) -> -1666.6667 | G38: =-IF(G$16<2027+$D$11,$D$4/$D$11,0) -> 0 | H38: =-IF(H$16<2027+$D$11,$D$4/$D$11,0) -> 0 | I38: =-IF(I$16<2027+$D$11,$D$4/$D$11,0) -> 0 | J38: =-IF(J$16<2027+$D$11,$D$4/$D$11,0) -> 0 | K38: =-IF(K$16<2027+$D$11,$D$4/$D$11,0) -> 0 | ... U38: =-IF(U$16<2027+$D$11,$D$4/$D$11,0) -> 0
B39: Less: decommissioning (final year, not deductible) | D39: =-IF(D$16=2027+$D$11+$D$9-1,$D$10,0) -> 0 | E39: =-IF(E$16=2027+$D$11+$D$9-1,$D$10,0) -> 0 | F39: =-IF(F$16=2027+$D$11+$D$9-1,$D$10,0) -> 0 | G39: =-IF(G$16=2027+$D$11+$D$9-1,$D$10,0) -> 0 | H39: =-IF(H$16=2027+$D$11+$D$9-1,$D$10,0) -> 0 | I39: =-IF(I$16=2027+$D$11+$D$9-1,$D$10,0) -> 0 | J39: =-IF(J$16=2027+$D$11+$D$9-1,$D$10,0) -> 0 | K39: =-IF(K$16=2027+$D$11+$D$9-1,$D$10,0) -> 0 | ... U39: =-IF(U$16=2027+$D$11+$D$9-1,$D$10,0) -> -350
B40: Unlevered free cash flow (used in leverage test) | D40: =D34+D37+D38+D39 -> -1666.6667 | E40: =E34+E37+E38+E39 -> -1666.6667 | F40: =F34+F37+F38+F39 -> -1666.6667 | G40: =G34+G37+G38+G39 -> 1491.3878 | H40: =H34+H37+H38+H39 -> 1486.5724 | I40: =I34+I37+I38+I39 -> 1481.7571 | J40: =J34+J37+J38+J39 -> 1476.9417 | K40: =K34+K37+K38+K39 -> 1472.1264 | ... U40: =U34+U37+U38+U39 -> -30.778745
B41: Less: carbon cost @ $75/t (valuation only) | D41: =-D18*$D$12*'WACC & Inputs'!$C$5/1000 -> 0 | E41: =-E18*$D$12*'WACC & Inputs'!$C$5/1000 -> 0 | F41: =-F18*$D$12*'WACC & Inputs'!$C$5/1000 -> 0 | G41: =-G18*$D$12*'WACC & Inputs'!$C$5/1000 -> -78.01875 | H41: =-H18*$D$12*'WACC & Inputs'!$C$5/1000 -> -78.01875 | I41: =-I18*$D$12*'WACC & Inputs'!$C$5/1000 -> -78.01875 | J41: =-J18*$D$12*'WACC & Inputs'!$C$5/1000 -> -78.01875 | K41: =-K18*$D$12*'WACC & Inputs'!$C$5/1000 -> -78.01875 | ... U41: =-U18*$D$12*'WACC & Inputs'!$C$5/1000 -> -14.360651
...

Sheet Puma DCF
B1: Project Puma: DCF, IRR and leverage check
B2: $ in millions unless stated. Costs shown as negatives. Green = linked to exhibits, black = formula. Carbon is deducted for valuation only (rows 41-42), never in the leverage test.
B3: Inputs (linked)
B4: Development cost ($MM) | D4: ='Exhibit 1'!C33*1000 -> 15000
B5: Production royalty and government take (% of revenue) | D5: ='Exhibit 1'!C34 -> 0.2
B6: Direct operating expense ($/boe) | D6: ='Exhibit 1'!C35 -> 8
B7: Overhead expense ($/boe) | D7: ='Exhibit 1'!C36 -> 3.5
B8: Midstream expense ($/boe) | D8: ='Exhibit 1'!C38 -> 4
B9: Depreciation / producing life (years) | D9: ='Exhibit 1'!C37 -> 25
B10: Undiscounted decommissioning ($MM, final year) | D10: ='Exhibit 1'!C39 -> 1000
B11: Development years (time to production) | D11: ='Exhibit 1'!C40 -> 5
B12: Carbon intensity (kg CO2e/boe) | D12: ='Exhibit 10'!F5 -> 8
B13: Corporate tax rate | D13: ='WACC & Inputs'!$C$11 -> 0.21
B14: WACC used | D14: ='WACC & Inputs'!G48 -> 0.10617619
